Workbook

Sheet Individual CPAs
B2: CPA | C2: DMSO
B3: Replicate | C3: 1 | D3: 2 | E3: 3 | F3: 4 | G3: 5 | H3: 6 | I3: Average | J3: SD
A4: CPA molarity | B4: 0.5 | C4: 96.42208 | D4: 100.1813 | E4: 90.68607 | F4: 90.10221 | G4: 92.2766 | H4: 90.66887 | I4: =AVERAGE(C4:H4) -> 93.389522 | J4: =_xlfn.STDEV.P(C4:H4) -> 3.6986545
B5: 1 | C5: 80.23301 | D5: 79.45566 | E5: 86.53166 | F5: 74.34898 | G5: 86.09789 | H5: 79.96432 | I5: =AVERAGE(C5:H5) -> 81.105253 | J5: =_xlfn.STDEV.P(C5:H5) -> 4.1793786
B6: 1.5 | C6: 78.80456 | D6: 73.17319 | E6: 69.77999 | F6: 64.54037 | G6: 75.03599 | H6: 76.83374 | I6: =AVERAGE(C6:H6) -> 73.027973 | J6: =_xlfn.STDEV.P(C6:H6) -> 4.7345334
B7: 2 | C7: 71.59431 | D7: 64.49431 | E7: 64.15144 | F7: 54.58313 | G7: 66.06688 | H7: 71.48147 | I7: =AVERAGE(C7:H7) -> 65.395257 | J7: =_xlfn.STDEV.P(C7:H7) -> 5.7035398
B8: 2.5 | C8: 63.97592 | D8: 61.38545 | E8: 62.00722 | F8: 57.25821 | G8: 70.95006 | H8: 67.84596 | I8: =AVERAGE(C8:H8) -> 63.903803 | J8: =_xlfn.STDEV.P(C8:H8) -> 4.4590465
B9: 3 | C9: 55.81336 | D9: 56.0745 | E9: 58.25485 | F9: 63.05421 | G9: 63.57546 | H9: 65.82624 | I9: =AVERAGE(C9:H9) -> 60.433103 | J9: =_xlfn.STDEV.P(C9:H9) -> 3.8926163
B10: 3.5 | C10: 47.71883 | D10: 55.81543 | E10: 48.20385 | F10: 49.97606 | G10: 60.88473 | H10: 61.58481 | I10: =AVERAGE(C10:H10) -> 54.030618 | J10: =_xlfn.STDEV.P(C10:H10) -> 5.7367173
B11: 4 | C11: 33.97853 | D11: 33.14671 | E11: 33.5964 | F11: 32.88529 | G11: 41.94995 | H11: 48.65857 | I11: =AVERAGE(C11:H11) -> 37.369242 | J11: =_xlfn.STDEV.P(C11:H11) -> 5.9455681
B12: 4.5 | C12: 28.60485 | D12: 27.64145 | E12: 26.89573 | F12: 21.88775 | G12: 31.08737 | H12: 38.15599 | I12: =AVERAGE(C12:H12) -> 29.045523 | J12: =_xlfn.STDEV.P(C12:H12) -> 4.9191918
B13: 5 | C13: 13.64016 | D13: 11.83811 | E13: 12.28828 | F13: 11.33605 | G13: 21.71963 | H13: 29.16821 | I13: =AVERAGE(C13:H13) -> 16.665073 | J13: =_xlfn.STDEV.P(C13:H13) -> 6.6065807
B15: CPA | C15: Glycerol
B16: Replicate | C16: 1 | D16: 2 | E16: 3 | F16: 4 | G16: 5 | H16: 6 | I16: Average | J16: SD
A17: CPA molarity | B17: 0.5 | C17: 104.2445 | D17: 104.3265 | E17: 97.92279 | F17: 98.87052 | G17: 94.07042 | H17: 96.52607 | I17: =AVERAGE(C17:H17) -> 99.3268 | J17: =_xlfn.STDEV.P(C17:H17) -> 3.8042482
B18: 1 | C18: 102.2719 | D18: 99.53367 | E18: 91.22213 | F18: 95.15514 | G18: 95.16665 | H18: 97.23298 | I18: =AVERAGE(C18:H18) -> 96.763745 | J18: =_xlfn.STDEV.P(C18:H18) -> 3.5137885
B19: 1.5 | C19: 97.4424 | D19: 100.5052 | E19: 79.42895 | F19: 89.35914 | G19: 89.2869 | H19: 92.99155 | I19: =AVERAGE(C19:H19) -> 91.502357 | J19: =_xlfn.STDEV.P(C19:H19) -> 6.7555135
B20: 2 | C20: 91.32048 | D20: 87.48687 | E20: 80.36705 | F20: 83.11729 | G20: 87.39342 | H20: 85.01363 | I20: =AVERAGE(C20:H20) -> 85.783123 | J20: =_xlfn.STDEV.P(C20:H20) -> 3.4926295
B21: 2.5 | C21: 91.59257 | D21: 87.48687 | E21: 78.75889 | F21: 80.73944 | G21: 86.89514 | H21: 85.41758 | I21: =AVERAGE(C21:H21) -> 85.148415 | J21: =_xlfn.STDEV.P(C21:H21) -> 4.2892131
B22: 3 | C22: 95.1977 | D22: 88.97653 | E22: 78.8929 | F22: 74.34898 | G22: 82.21127 | H22: 84.00377 | I22: =AVERAGE(C22:H22) -> 83.938525 | J22: =_xlfn.STDEV.P(C22:H22) -> 6.7398799
B23: 3.5 | C23: 87.71535 | D23: 84.18371 | E23: 67.90381 | F23: 72.71421 | G23: 84.20441 | H23: 82.69095 | I23: =AVERAGE(C23:H23) -> 79.902073 | J23: =_xlfn.STDEV.P(C23:H23) -> 7.0862701
B24: 4 | C24: 75.4035 | D24: 80.88055 | E24: 55.03853 | F24: 47.44959 | G24: 81.81265 | H24: 76.73276 | I24: =AVERAGE(C24:H24) -> 69.55293 | J24: =_xlfn.STDEV.P(C24:H24) -> 13.31428
B25: 4.5 | C25: 51.1199 | D25: 56.39834 | E25: 34.40048 | F25: 28.27821 | G25: 57.29709 | H25: 53.80887 | I25: =AVERAGE(C25:H25) -> 46.883815 | J25: =_xlfn.STDEV.P(C25:H25) -> 11.305349
B26: 5 | C26: 29.08099 | D26: 27.96528 | E26: 15.77262 | F26: 11.03882 | G26: 35.77123 | H26: 33.10668 | I26: =AVERAGE(C26:H26) -> 25.455937 | J26: =_xlfn.STDEV.P(C26:H26) -> 8.9999707
B28: CPA | C28: PD (12PD)
B29: Replicate | C29: 1 | D29: 2 | E29: 3 | F29: 4 | G29: 5 | H29: 6 | I29: Average | J29: SD
A30: CPA molarity | B30: 0.5 | C30: 105.4689 | D30: 106.982 | E30: 102.2112 | F30: 95.45237 | G30: 95.06699 | H30: 96.42508 | I30: =AVERAGE(C30:H30) -> 100.26776 | J30: =_xlfn.STDEV.P(C30:H30) -> 4.8461671
B31: 1 | C31: 94.92561 | D31: 96.42482 | E31: 88.54186 | F31: 90.99391 | G31: 90.28347 | H31: 91.07281 | I31: =AVERAGE(C31:H31) -> 92.040413 | J31: =_xlfn.STDEV.P(C31:H31) -> 2.7357367
B32: 1.5 | C32: 100.1633 | D32: 91.37293 | E32: 87.87179 | F32: 90.39945 | G32: 90.38312 | H32: 89.86098 | I32: =AVERAGE(C32:H32) -> 91.675262 | J32: =_xlfn.STDEV.P(C32:H32) -> 3.9410984
B33: 2 | C33: 96.83021 | D33: 95.32377 | E33: 90.15002 | F33: 88.0216 | G33: 88.68896 | H33: 89.05309 | I33: =AVERAGE(C33:H33) -> 91.344608 | J33: =_xlfn.STDEV.P(C33:H33) -> 3.4326497
B34: 2.5 | C34: 96.69416 | D34: 97.65541 | E34: 89.61397 | F34: 87.27852 | G34: 89.08759 | H34: 91.37577 | I34: =AVERAGE(C34:H34) -> 91.950903 | J34: =_xlfn.STDEV.P(C34:H34) -> 3.8914788
B35: 3 | C35: 97.51042 | D35: 93.57504 | E35: 85.32554 | F35: 75.09206 | G35: 89.58587 | H35: 88.14421 | I35: =AVERAGE(C35:H35) -> 88.205523 | J35: =_xlfn.STDEV.P(C35:H35) -> 7.0424801
B36: 3.5 | C36: 89.75599 | D36: 88.32885 | E36: 81.17113 | F36: 68.25575 | G36: 86.19754 | H36: 81.37813 | I36: =AVERAGE(C36:H36) -> 82.514565 | J36: =_xlfn.STDEV.P(C36:H36) -> 7.1439783
B37: 4 | C37: 67.98918 | D37: 71.23016 | E37: 57.18274 | F37: 48.78713 | G37: 66.06688 | H37: 77.23769 | I37: =AVERAGE(C37:H37) -> 64.748963 | J37: =_xlfn.STDEV.P(C37:H37) -> 9.3295049
B38: 4.5 | C38: 7.450222 | D38: 4.519351 | E38: 13.76242 | F38: 13.7139 | G38: 7.468719 | H38: 35.22739 | I38: =AVERAGE(C38:H38) -> 13.690334 | J38: =_xlfn.STDEV.P(C38:H38) -> 10.211145
B39: 5 | C39: 0.0359 | D39: 0.115143 | E39: 2.505305 | F39: 2.419128 | G39: 0.193777 | H39: 15.53506 | I39: =AVERAGE(C39:H39) -> 3.4673855 | J39: =_xlfn.STDEV.P(C39:H39) -> 5.4982171
B41: CPA | C41: EG
B42: Replicate | C42: 1 | D42: 2 | E42: 3 | F42: 4 | G42: 5 | H42: 6 | I42: Average | J42: SD
A43: CPA molarity | B43: 0.5 | C43: 108.7339 | D43: 105.6866 | E43: 97.25273 | F43: 99.16775 | G43: 95.76459 | H43: 97.33396 | I43: =AVERAGE(C43:H43) -> 100.65659 | J43: =_xlfn.STDEV.P(C43:H43) -> 4.8186855
B44: 1 | C44: 110.3664 | D44: 113.1349 | E44: 99.66497 | F44: 104.5179 | G44: 96.26287 | H44: 97.63692 | I44: =AVERAGE(C44:H44) -> 103.59733 | J44: =_xlfn.STDEV.P(C44:H44) -> 6.3563255
...

Sheet Cocktails
A1: CPA | B1: Glycerol | C1: DMSO | D1: EG | E1: 12PD | F1: 13PD | G1: 3M12PD | H1: Urea | I1: Total molarity | J1: % viability
A2: 1 | B2: 3.5 | C2: 0 | D2: 0 | E2: 0 | F2: 0 | G2: 0 | H2: 0 | I2: =SUM(B2:E2) -> 3.5 | J2: 88.494263
A3: 2 | B3: 0 | C3: 3.5 | D3: 0 | E3: 0 | F3: 0 | G3: 0 | H3: 0 | I3: =SUM(B3:E3) -> 3.5 | J3: 58.737419
A4: 3 | B4: 0 | C4: 0 | D4: 3.5 | E4: 0 | F4: 0 | G4: 0 | H4: 0 | I4: =SUM(B4:E4) -> 3.5 | J4: 97.503974
A5: 4 | B5: 3 | C5: 0 | D5: 0.5 | E5: 0 | F5: 0 | G5: 0 | H5: 0 | I5: =SUM(B5:E5) -> 3.5 | J5: 93.760589
A6: 5 | B6: 3 | C6: 0.5 | D6: 0 | E6: 0 | F6: 0 | G6: 0 | H6: 0 | I6: =SUM(B6:E6) -> 3.5 | J6: 87.848772
A7: 6 | B7: 2.5 | C7: 1 | D7: 0 | E7: 0 | F7: 0 | G7: 0 | H7: 0 | I7: =SUM(B7:E7) -> 3.5 | J7: 79.500012
A8: 7 | B8: 2.5 | C8: 0 | D8: 1 | E8: 0 | F8: 0 | G8: 0 | H8: 0 | I8: =SUM(B8:E8) -> 3.5 | J8: 89.992049
A9: 8 | B9: 2.5 | C9: 0.5 | D9: 0.5 | E9: 0 | F9: 0 | G9: 0 | H9: 0 | I9: =SUM(B9:E9) -> 3.5 | J9: 93.018742
A10: 9 | B10: 2 | C10: 1.5 | D10: 0 | E10: 0 | F10: 0 | G10: 0 | H10: 0 | I10: =SUM(B10:E10) -> 3.5 | J10: 69.792163
A11: 10 | B11: 2 | C11: 1 | D11: 0.5 | E11: 0 | F11: 0 | G11: 0 | H11: 0 | I11: =SUM(B11:E11) -> 3.5 | J11: 81.516741
A12: 11 | B12: 2 | C12: 0 | D12: 1.5 | E12: 0 | F12: 0 | G12: 0 | H12: 0 | I12: =SUM(B12:E12) -> 3.5 | J12: 92.774995
A13: 12 | B13: 2 | C13: 0.5 | D13: 1 | E13: 0 | F13: 0 | G13: 0 | H13: 0 | I13: =SUM(B13:E13) -> 3.5 | J13: 86.096369
... A211: 210 | B211: 0.5 | C211: 1.5 | D211: 1 | E211: 2 | F211: 0 | G211: 0 | H211: 0 | I211: =SUM(B211:E211) -> 5 | J211: 53.449418
A212: 211 | B212: 0.5 | C212: 0.5 | D212: 1 | E212: 1 | F212: 1 | G212: 1 | H212: 0 | I212: =SUM(B212:G212) -> 5 | J212: 61.72971
A213: 212 | B213: 0.5 | C213: 0.5 | D213: 0.5 | E213: 0.5 | F213: 1.5 | G213: 1.5 | H213: 0 | I213: =SUM(B213:G213) -> 5 | J213: 37.991215
A214: 213 | B214: 1 | C214: 1 | D214: 0.5 | E214: 0.5 | F214: 1 | G214: 1 | H214: 0 | I214: =SUM(B214:G214) -> 5 | J214: 47.231753
A215: 214 | B215: 0.5 | C215: 0.5 | D215: 1 | E215: 1 | F215: 0.5 | G215: 1.5 | H215: 0 | I215: =SUM(B215:G215) -> 5 | J215: 53.634155
A216: 215 | B216: 0.5 | C216: 0.5 | D216: 0.5 | E216: 0.5 | F216: 2 | G216: 1 | H216: 0 | I216: =SUM(B216:G216) -> 5 | J216: 52.143445
A217: 216 | B217: 1 | C217: 1 | D217: 1 | E217: 1 | F217: 0.5 | G217: 0.5 | H217: 0 | I217: =SUM(B217:G217) -> 5 | J217: 63.722657
A218: 217 | B218: 0 | C218: 0 | D218: 1 | E218: 0 | F218: 2 | G218: 2 | H218: 0 | I218: =SUM(B218:G218) -> 5 | J218: 54.580056
A219: 218 | B219: 1 | C219: 0 | D219: 0 | E219: 0 | F219: 2 | G219: 2 | H219: 0 | I219: =SUM(B219:G219) -> 5 | J219: 34.977852
A220: 219 | B220: 0 | C220: 0 | D220: 0 | E220: 1 | F220: 2 | G220: 2 | H220: 0 | I220: =SUM(B220:G220) -> 5 | J220: 47.658999
A221: 220 | B221: 2 | C221: 0 | D221: 0 | E221: 0 | F221: 2 | G221: 1 | H221: 0 | I221: =SUM(B221:G221) -> 5 | J221: 60.808597
A222: 221 | B222: 0 | C222: 2 | D222: 0 | E222: 0 | F222: 2 | G222: 1 | H222: 0 | I222: =SUM(B222:G222) -> 5 | J222: 34.558347
A223: 222 | B223: 0 | C223: 2 | D223: 0 | E223: 0 | F223: 1 | G223: 2 | H223: 0 | I223: =SUM(B223:G223) -> 5 | J223: 38.26145
... A295: 294 | B295: 0 | C295: 0 | D295: 0 | E295: 1.5 | F295: 1.5 | G295: 2 | H295: 0 | I295: =SUM(B295:G295) -> 5 | J295: 26.794367
A296: 295 | B296: 1 | C296: 0.5 | D296: 0.5 | E296: 0.5 | F296: 0.5 | G296: 0.5 | H296: 0.5 | I296: =SUM(B296:H296) -> 4 | J296: 79.010203
A297: 296 | B297: 0.5 | C297: 0.5 | D297: 1 | E297: 0.5 | F297: 0.5 | G297: 0.5 | H297: 0.5 | I297: =SUM(B297:H297) -> 4 | J297: 69.431381
A298: 297 | B298: 0.5 | C298: 0.5 | D298: 0.5 | E298: 1 | F298: 0.5 | G298: 0.5 | H298: 0.5 | I298: =SUM(B298:H298) -> 4 | J298: 66.999357
A299: 298 | B299: 0.5 | C299: 0.5 | D299: 0.5 | E299: 0.5 | F299: 1 | G299: 0.5 | H299: 0.5 | I299: =SUM(B299:H299) -> 4 | J299: 62.737715
A300: 299 | B300: 0.5 | C300: 0.5 | D300: 0.5 | E300: 0.5 | F300: 0.5 | G300: 1 | H300: 0.5 | I300: =SUM(B300:H300) -> 4 | J300: 68.7337
A301: 300 | B301: 0.5 | C301: 1 | D301: 0.5 | E301: 0.5 | F301: 0.5 | G301: 0.5 | H301: 0.5 | I301: =SUM(B301:H301) -> 4 | J301: 68.511079
A302: 301 | B302: 1 | C302: 1 | D302: 0 | E302: 0 | F302: 1 | G302: 1 | H302: 0.5 | I302: =SUM(B302:H302) -> 4.5 | J302: 64.691836
A303: 302 | B303: 1 | C303: 1 | D303: 0 | E303: 0 | F303: 1 | G303: 1 | H303: 0 | I303: =SUM(B303:H303) -> 4 | J303: 48.017799
A304: 303 | B304: 0 | C304: 1 | D304: 1 | E304: 0 | F304: 1 | G304: 1 | H304: 0.5 | I304: =SUM(B304:H304) -> 4.5 | J304: 63.788501
A305: 304 | B305: 0 | C305: 1 | D305: 1 | E305: 0 | F305: 1 | G305: 1 | H305: 0 | I305: =SUM(B305:H305) -> 4 | J305: 65.211566
A306: 305 | B306: 0 | C306: 1 | D306: 0 | E306: 1 | F306: 1 | G306: 1 | H306: 0.5 | I306: =SUM(B306:H306) -> 4.5 | J306: 55.177153
A307: 306 | B307: 0 | C307: 1 | D307: 0 | E307: 1 | F307: 1 | G307: 1 | H307: 0 | I307: =SUM(B307:H307) -> 4 | J307: 66.303542
... A424: 423 | B424: 3.5 | C424: 0 | D424: 0 | E424: 0.5 | F424: 0.5 | G424: 0.5 | H424: 0 | I424: =SUM(B424:H424) -> 5 | J424: 73.949611
...
